<sdf version='1.5'>
  <model name='naoType0'>
    <link name='base_link'>
      <pose>0 0 0 0 -0 0</pose>
      <inertial>
        <pose>0 0 0 0 -0 0</pose>
        <mass>1.2171</mass>
        <inertia>
          <ixx>0.0043004</ixx>
          <iyy>0.0043004</iyy>
          <izz>0.0020285</izz>
          <ixy>0</ixy>
          <ixz>0</ixz>
          <iyz>0</iyz>
        </inertia>
      </inertial>
      <collision name='base_link_collision'>
        <pose>0 0 0 0 0 0</pose>
        <geometry>
          <box>
            <size>0.1 0.1 0.18</size>
          </box>
        </geometry>
      </collision>
      <visual name='base_link_visual'>
        <pose>0 0 -0.03 0 -0 0</pose>
        <geometry>
          <mesh>
            <scale>0.1 0.11 0.11</scale>
            <uri>model://nao_blue/meshes/V40/Torso.dae</uri>
          </mesh>
        </geometry>
      </visual>
      <gravity>1</gravity>
      <velocity_decay/>
      <self_collide>0</self_collide>
    </link>
    <link name='Neck'>
      <pose>0 0 0.09 0 0 0</pose>
      <inertial>
        <pose>0 0 0 0 -0 0</pose>
        <mass>0.05</mass>
        <inertia>
          <ixx>0.000029479</ixx>
          <iyy>0.000029479</iyy>
          <izz>0.000005625</izz>
          <ixy>0</ixy>
          <ixz>0</ixz>
          <iyz>0</iyz>
        </inertia>
      </inertial>
      <visual name='Neck_visual'>
        <pose>0 0 0.0 0 -0 0</pose>
        <geometry>
          <mesh>
            <scale>0.1 0.1 0.2</scale>
            <uri>model://nao_blue/meshes/V40/HeadYaw.dae</uri>
          </mesh>
        </geometry>
      </visual>
      <gravity>1</gravity>
      <velocity_decay/>
      <self_collide>0</self_collide>
    </link>
    <joint name='HeadYaw' type='revolute'>
      <child>Neck</child>
      <parent>base_link</parent>
      <axis>
        <xyz>0 0 1</xyz>
        <limit>
          <lower>-2.0943951</lower>
          <upper>2.0943951</upper>
          <effort>40.25</effort>
          <velocity>8.26797</velocity>
        </limit>
        <dynamics>
          <damping>0.1</damping>
          <friction>0</friction>
          <spring_reference>0</spring_reference>
          <spring_stiffness>0</spring_stiffness>
        </dynamics>
        <use_parent_model_frame>1</use_parent_model_frame>
      </axis>
      <physics>
        <ode>
          <implicit_spring_damper>1</implicit_spring_damper>
          <cfm_damping>1</cfm_damping>
          <limit>
            <cfm>0</cfm>
            <erp>0.2</erp>
          </limit>
        </ode>
      </physics>
    </joint>
    <link name='Head'>
      <pose>0 0 0.155 0 0 0</pose>
      <inertial>
        <pose>0.0 0 0 0 0 0</pose>
        <mass>0.35</mass>
        <inertia>
          <ixx>0.0005915</ixx>
          <iyy>0.0005915</iyy>
          <izz>0.0005915</izz>
          <ixy>0</ixy>
          <ixz>0</ixz>
          <iyz>0</iyz>
        </inertia>
      </inertial>
      <collision name='Head_collision'>
        <pose>0 0 0 0 0 0</pose>
        <geometry>
          <sphere>
            <radius>0.065</radius>
          </sphere>
        </geometry>
        <surface>
          <contact>
            <ode/>
          </contact>
          <friction>
            <ode>
              <mu>0.5</mu>
              <mu2>0.5</mu2>
            </ode>
          </friction>
        </surface>
      </collision>
      <visual name='Head_visual'>
        <pose>0 0 -0.055 0 -0 0</pose>
        <geometry>
          <mesh>
            <scale>0.1 0.1 0.12</scale>
            <uri>model://nao_blue/meshes/V40/HeadPitch.dae</uri>
          </mesh>
        </geometry>
      </visual>
      <velocity_decay/>
      <gravity>1</gravity>
      <velocity_decay/>
      <self_collide>0</self_collide>
    </link>
    <joint name='HeadPitch' type='revolute'>
      <child>Head</child>
      <pose>0 0 -0.005 0 0 0</pose>
      <parent>Neck</parent>
      <axis>
        <xyz>0 -1 0</xyz>
        <limit>
          <lower>-0.785398</lower>
          <upper>0.785398</upper>
          <effort>40.25</effort>
          <velocity>6.1395</velocity>
        </limit>
        <dynamics>
          <damping>0.1</damping>
          <friction>0</friction>
          <spring_reference>0</spring_reference>
          <spring_stiffness>0</spring_stiffness>
        </dynamics>
        <use_parent_model_frame>1</use_parent_model_frame>
      </axis>
      <physics>
        <ode>
          <implicit_spring_damper>1</implicit_spring_damper>
          <cfm_damping>1</cfm_damping>
          <limit>
            <cfm>0</cfm>
            <erp>0.2</erp>
          </limit>
        </ode>
      </physics>
    </joint>
    <link name='LHip1'>
      <pose>0 0.055 -0.115 0 -0 0</pose>
      <inertial>
        <pose>-0.0 0.0 0.0 0 -0 0</pose>
        <mass>0.09</mass>
        <inertia>
          <ixx>0.0000036</ixx>
          <iyy>0.0000036</iyy>
          <izz>0.0000036</izz>
          <ixy>0</ixy>
          <ixz>0</ixz>
          <iyz>0</iyz>
        </inertia>
      </inertial>
      <visual name='LHip1_visual'>
        <pose>0 0 0 0 -0 0</pose>
        <geometry>
          <mesh>
            <scale>0.1 0.1 0.1</scale>
            <uri>model://nao_blue/meshes/V40/LHipYawPitch.dae</uri>
          </mesh>
        </geometry>
      </visual>
      <gravity>1</gravity>
      <velocity_decay/>
      <self_collide>0</self_collide>
    </link>
    <joint name='LHipYawPitch' type='revolute'>
      <child>LHip1</child>
	  <pose>-0.01 0 0 0 0 0</pose>		
      <parent>base_link</parent>
      <axis>
        <xyz>0 0.7071 -0.7071</xyz>
        <limit>
          <lower>-1.57079</lower>
          <upper>0.017453</upper>
          <effort>100</effort>
          <velocity>6.1395</velocity>
        </limit>
        <dynamics>
          <damping>0.1</damping>
          <friction>0</friction>
          <spring_reference>0</spring_reference>
          <spring_stiffness>0</spring_stiffness>
        </dynamics>
        <use_parent_model_frame>1</use_parent_model_frame>
      </axis>
      <physics>
        <ode>
          <implicit_spring_damper>1</implicit_spring_damper>
          <cfm_damping>1</cfm_damping>
          <limit>
            <cfm>0</cfm>
            <erp>0.2</erp>
          </limit>
        </ode>
      </physics>
    </joint>
    <link name='LHip'>
      <pose>0 0.055 -0.115 0 -0 0</pose>
      <inertial>
        <pose>0 0 -0 0 -0 0</pose>
        <mass>0.125</mass>
        <inertia>
          <ixx>0.000005</ixx>
          <iyy>0.000005</iyy>
          <izz>0.000005</izz>
          <ixy>0</ixy>
          <ixz>0</ixz>
          <iyz>0</iyz>
        </inertia>
      </inertial>
      <visual name='LHip_visual'>
        <pose>0 0 0 0 -0 0</pose>
        <geometry>
          <mesh>
            <scale>0.1 0.1 0.1</scale>
            <uri>model://nao_blue/meshes/V40/LHipRoll.dae</uri>
          </mesh>
        </geometry>
      </visual>
      <gravity>1</gravity>
      <velocity_decay/>
      <self_collide>0</self_collide>
    </link>
    <joint name='LHipRoll' type='revolute'>
      <child>LHip</child>
	  <pose>-0.01 0 0 0 0 0</pose>				
      <parent>LHip1</parent>
      <axis>
        <xyz>1 0 0</xyz>
        <limit>
          <lower>-0.436332</lower>
          <upper>0.785398</upper>
          <effort>200</effort>
          <velocity>6.1395</velocity>
        </limit>
        <dynamics>
          <damping>0.1</damping>
          <friction>0</friction>
          <spring_reference>0</spring_reference>
          <spring_stiffness>0</spring_stiffness>
        </dynamics>
        <use_parent_model_frame>1</use_parent_model_frame>
      </axis>
      <physics>
        <ode>
          <implicit_spring_damper>1</implicit_spring_damper>
          <cfm_damping>1</cfm_damping>
          <limit>
            <cfm>0</cfm>
            <erp>0.2</erp>
          </limit>
        </ode>
      </physics>
    </joint>
    <link name='LThigh'>
      <pose>0 0.055 -0.155 0 -0 0</pose>
      <inertial>
        <pose>0.0 0.0 0 0 -0 0</pose>
        <mass>0.275</mass>
        <inertia>
          <ixx>0.00056145</ixx>
          <iyy>0.00056145</iyy>
          <izz>0.00022458</izz>
          <ixy>0</ixy>
          <ixz>0</ixz>
          <iyz>0</iyz>
        </inertia>
      </inertial>
      <collision name='LThigh_collision'>
        <pose>0 0 0 0 -0 0</pose>
        <geometry>
          <box>
            <size>0.070 0.070 0.14</size>
          </box>
        </geometry>
        <surface>
          <contact>
            <ode/>
          </contact>
          <friction>
            <ode>
              <mu>0.5</mu>
              <mu2>0.5</mu2>
            </ode>
          </friction>
        </surface>
      </collision>
      <visual name='LThigh_visual'>
        <pose>0.01 0 0.04 0 -0 0</pose>
        <geometry>
          <mesh>
            <scale>0.1 0.1 0.12</scale>
            <uri>model://nao_blue/meshes/V40/LHipPitch.dae</uri>
          </mesh>
        </geometry>
      </visual>
      <gravity>1</gravity>
      <velocity_decay/>
      <self_collide>0</self_collide>
    </link>
    <joint name='LHipPitch' type='revolute'>
      <child>LThigh</child>
      <pose>-0.01 0 0.04 0 -0 0</pose>
      <parent>LHip</parent>
      <axis>
        <xyz>0 -1 0</xyz>
        <limit>
          <lower>-0.436332</lower>
          <upper>1.53589</upper>
          <effort>300</effort>
          <velocity>6.40239</velocity>
        </limit>
        <dynamics>
          <damping>0.1</damping>
          <friction>0</friction>
          <spring_reference>0</spring_reference>
          <spring_stiffness>0</spring_stiffness>
        </dynamics>
        <use_parent_model_frame>1</use_parent_model_frame>
      </axis>
      <physics>
        <ode>
          <implicit_spring_damper>1</implicit_spring_damper>
          <cfm_damping>1</cfm_damping>
          <limit>
            <cfm>0</cfm>
            <erp>0.2</erp>
          </limit>
        </ode>
      </physics>
    </joint>
    <link name='LTibia'>
      <pose>0.005 0.055 -0.280 0 -0 0</pose>
      <inertial>
        <pose>0 0 0 0 -0 0</pose>
        <mass>0.225 </mass>
        <inertia>
          <ixx>0.0003468</ixx>
          <iyy>0.0003187</iyy>
          <izz>0.0002118</izz>
          <ixy>0</ixy>
          <ixz>0</ixz>
          <iyz>0</iyz>
        </inertia>
      </inertial>
      <collision name='LTibia_collision'>
        <pose>0 0 0.0 0 -0 0</pose>
        <geometry>
          <box>
            <size>0.070 0.080 0.11</size>
          </box>
        </geometry>
        <surface>
          <contact>
            <ode/>
          </contact>
          <friction>
            <ode>
              <mu>0.5</mu>
              <mu2>0.5</mu2>
            </ode>
          </friction>
        </surface>
      </collision>
      <visual name='LTibia_visual'>
        <pose>0 0 0.05 0 -0 0</pose>
        <geometry>
          <mesh>
            <scale>0.1 0.1 0.11</scale>
            <uri>model://nao_blue/meshes/V40/LKneePitch.dae</uri>
          </mesh>
        </geometry>
      </visual>
      <gravity>1</gravity>
      <velocity_decay/>
      <self_collide>0</self_collide>
    </link>
    <joint name='LKneePitch' type='revolute'>
      <child>LTibia</child>
      <pose>0 0 0.045 0 -0 0</pose>
      <parent>LThigh</parent>
      <axis>
        <xyz>0 -1 0</xyz>
        <limit>
          <lower>-2.268928</lower>
          <upper>0.017453</upper>
          <effort>300</effort>
          <velocity>6.40239</velocity>
        </limit>
        <dynamics>
          <damping>0.1</damping>
          <friction>0</friction>
          <spring_reference>0</spring_reference>
          <spring_stiffness>0</spring_stiffness>
        </dynamics>
        <use_parent_model_frame>1</use_parent_model_frame>
      </axis>
      <physics>
        <ode>
          <implicit_spring_damper>1</implicit_spring_damper>
          <cfm_damping>1</cfm_damping>
          <limit>
            <cfm>0</cfm>
            <erp>0.2</erp>
          </limit>
        </ode>
      </physics>
    </joint>
    <link name='l_ankle'>
      <pose>0 0.055 -0.335 0 -0 0</pose>
      <inertial>
        <pose>0.00045 0.00029 0.00685 0 -0 0</pose>
        <mass>0.125 </mass>
        <inertia>
          <ixx>0.000005</ixx>
          <iyy>0.000005</iyy>
          <izz>0.000005</izz>
          <ixy>0</ixy>
          <ixz>0</ixz>
          <iyz>0</iyz>
        </inertia>
      </inertial>
      <visual name='l_ankle_visual'>
        <pose>0 0 0 0 -0 0</pose>
        <geometry>
          <mesh>
            <scale>0.1 0.1 0.1</scale>
            <uri>model://nao_blue/meshes/V40/LAnklePitch.dae</uri>
          </mesh>
        </geometry>
      </visual>
      <gravity>1</gravity>
      <velocity_decay/>
      <self_collide>0</self_collide>
    </link>
    <joint name='LAnklePitch' type='revolute'>
      <child>l_ankle</child>
      <pose>-0.005 0 0 0 0 0</pose>
      <parent>LTibia</parent>
      <axis>
        <xyz>0 -1 0</xyz>
        <limit>
          <lower>-0.785398</lower>
          <upper>1.308996</upper>
          <effort>300</effort>
          <velocity>6.40239</velocity>
        </limit>
        <dynamics>
          <damping>0.1</damping>
          <friction>0</friction>
          <spring_reference>0</spring_reference>
          <spring_stiffness>0</spring_stiffness>
        </dynamics>
        <use_parent_model_frame>1</use_parent_model_frame>
      </axis>
      <physics>
        <ode>
          <implicit_spring_damper>1</implicit_spring_damper>
          <cfm_damping>1</cfm_damping>
          <limit>
            <cfm>0</cfm>
            <erp>0.2</erp>
          </limit>
        </ode>
      </physics>
    </joint>
    <link name='l_sole'>
      <pose>0 0.055 -0.375 0 -0 0</pose>
      <inertial>
        <pose>0.025 0 0 0 -0 0</pose>
        <mass>0.2</mass>
        <inertia>
          <ixx>0.00011333</ixx>
          <iyy>0.00043333</iyy>
          <izz>0.00053333</izz>
          <ixy>0</ixy>
          <ixz>0</ixz>
          <iyz>0</iyz>
        </inertia>
      </inertial>
      <collision name='l_sole_collision'>
        <pose>0.025 0.0 0.0 0 -0 0</pose>
        <geometry>
          <box>
            <size>0.16 0.08 0.02</size>
          </box>
        </geometry>
        <surface>
          <contact>
            <ode>
              <max_vel>0.1</max_vel>
              <min_depth>0.003</min_depth>
            </ode>
          </contact>
          <friction>
            <ode>
              <mu>0.5</mu>
              <mu2>0.5</mu2>
              <fdir1>1 0 0</fdir1>
            </ode>
          </friction>
        </surface>
      </collision>
      <visual name='l_sole_visual'>
        <pose>0 0 0.03 0 -0 0</pose>
        <geometry>
          <mesh>
            <scale>0.1 0.1 0.1</scale>
            <uri>model://nao_blue/meshes/V40/LAnkleRoll.dae</uri>
          </mesh>
        </geometry>
      </visual>
      <gravity>1</gravity>
      <velocity_decay/>
      <self_collide>0</self_collide>
    </link>
    <joint name='LAnkleRoll' type='revolute'>
      <child>l_sole</child>
      <pose>-0.005 0 0.04 0 -0 0</pose>
      <parent>l_ankle</parent>
      <axis>
        <xyz>1 0 0</xyz>
        <limit>
          <lower>-0.785398</lower>
          <upper>0.436332</upper>
          <effort>200</effort>
          <velocity>6.1395</velocity>
        </limit>
        <dynamics>
          <damping>0.1</damping>
          <friction>0</friction>
          <spring_reference>0</spring_reference>
          <spring_stiffness>0</spring_stiffness>
        </dynamics>
        <use_parent_model_frame>1</use_parent_model_frame>
      </axis>
      <physics>
        <ode>
          <implicit_spring_damper>1</implicit_spring_damper>
          <cfm_damping>1</cfm_damping>
          <limit>
            <cfm>0</cfm>
            <erp>0.2</erp>
          </limit>
        </ode>
      </physics>
    </joint>
    <link name='LShoulder'>
      <pose>0 0.098 0.075 0 -0 0</pose>
      <inertial>
        <pose>0 0 0 0 0 0</pose>
        <mass>0.07</mass>
        <inertia>
          <ixx>0</ixx>
          <ixy>0</ixy>
          <ixz>0</ixz>
          <iyy>0</iyy>
          <iyz>0</iyz>
          <izz>0</izz>
        </inertia>
      </inertial>
      <visual name='LShoulder_visual'>
        <pose>0 0 0 0 -0 0</pose>
        <geometry>
          <mesh>
            <scale>0.1 0.1 0.11</scale>
            <uri>model://nao_blue/meshes/V40/LShoulderPitch.dae</uri>
          </mesh>
        </geometry>
      </visual>
      <gravity>1</gravity>
      <velocity_decay/>
      <self_collide>0</self_collide>
    </link>
    <joint name='LShoulderPitch' type='revolute'>
      <child>LShoulder</child>
      <parent>base_link</parent>
      <axis>
        <xyz>0 -1 0</xyz>
        <limit>
          <lower>-2.094395</lower>
          <upper>2.094395</upper>
          <effort>40.25</effort>
          <velocity>6.1395</velocity>
        </limit>
        <dynamics>
          <damping>0.1</damping>
          <friction>0</friction>
          <spring_reference>0</spring_reference>
          <spring_stiffness>0</spring_stiffness>
        </dynamics>
        <use_parent_model_frame>1</use_parent_model_frame>
      </axis>
      <physics>
        <ode>
          <implicit_spring_damper>1</implicit_spring_damper>
          <cfm_damping>1</cfm_damping>
          <limit>
            <cfm>0</cfm>
            <erp>0.2</erp>
          </limit>
        </ode>
      </physics>
    </joint>
    <link name='LBicep'>
      <pose>0.02 0.108 0.075 0 -0 0</pose>
      <inertial>
        <pose>0 0 0 0 -0 0</pose>
        <mass>0.15</mass>
        <inertia>
          <ixx>0.00010625</ixx>
          <ixy>0</ixy>
          <ixz>0</ixz>
          <iyy>0.00014125</iyy>
          <iyz>0</iyz>
          <izz>0.000125</izz>
        </inertia>
      </inertial>
      <collision name='LBicep_collision'>
        <pose>0 0 0 0 0 0</pose>
        <geometry>
          <box>
            <size>0.08 0.07 0.06</size>
          </box>
        </geometry>
        <surface>
          <contact>
            <ode/>
          </contact>
          <friction>
            <ode>
              <mu>0.5</mu>
              <mu2>0.5</mu2>
            </ode>
          </friction>
        </surface>
      </collision>
      <visual name='LBicep_visual'>
        <pose>-0.02 -0.015 0 0 -0 0</pose>
        <geometry>
          <mesh>
            <scale>0.1 0.1 0.1</scale>
            <uri>model://nao_blue/meshes/V40/LShoulderRoll.dae</uri>
          </mesh>
        </geometry>
      </visual>
      <gravity>1</gravity>
      <velocity_decay/>
      <self_collide>0</self_collide>
    </link>
    <joint name='LShoulderRoll' type='revolute'>
      <child>LBicep</child>
      <pose>-0.02 -0.01 0 0 -0 0</pose>
      <parent>LShoulder</parent>
      <axis>
        <xyz>0 0 1</xyz>
        <limit>
          <lower>-0.017453</lower>
          <upper>1.658062</upper>
          <effort>40.25</effort>
          <velocity>6.1395</velocity>
        </limit>
        <dynamics>
          <damping>0.1</damping>
          <friction>0</friction>
          <spring_reference>0</spring_reference>
          <spring_stiffness>0</spring_stiffness>
        </dynamics>
        <use_parent_model_frame>1</use_parent_model_frame>
      </axis>
      <physics>
        <ode>
          <implicit_spring_damper>1</implicit_spring_damper>
          <cfm_damping>1</cfm_damping>
          <limit>
            <cfm>0</cfm>
            <erp>0.2</erp>
          </limit>
        </ode>
      </physics>
    </joint>
    <link name='LElbow'>
      <pose>0.09 0.098 0.084 0 -0 0</pose>
      <inertial>
        <pose>0 0 0 0 -0 0</pose>
        <mass>0.035</mass>
        <inertia>
          <ixx>0.0000014</ixx>
          <ixy>0</ixy>
          <ixz>0</ixz>
          <iyy>0.0000014</iyy>
          <iyz>0</iyz>
          <izz>0.0000014</izz>
        </inertia>
      </inertial>
      <gravity>1</gravity>
      <velocity_decay/>
      <self_collide>0</self_collide>
    </link>
    <joint name='LElbowYaw' type='revolute'>
      <child>LElbow</child>
      <parent>LBicep</parent>
      <axis>
        <xyz>1 0 0</xyz>
        <limit>
          <lower>-2.094395</lower>
          <upper>2.094395</upper>
          <effort>40.25</effort>
          <velocity>6.1395</velocity>
        </limit>
        <dynamics>
          <damping>0.1</damping>
          <friction>0</friction>
          <spring_reference>0</spring_reference>
          <spring_stiffness>0</spring_stiffness>
        </dynamics>
        <use_parent_model_frame>1</use_parent_model_frame>
      </axis>
      <physics>
        <ode>
          <implicit_spring_damper>1</implicit_spring_damper>
          <cfm_damping>1</cfm_damping>
          <limit>
            <cfm>0</cfm>
            <erp>0.2</erp>
          </limit>
        </ode>
      </physics>
    </joint>
    <link name='LForeArm'>
      <pose>0.14 0.098 0.084 0 -0 0</pose>
      <inertial>
        <pose>0.0 0.0 0.0 0 -0 0</pose>
        <mass>0.2</mass>
        <inertia>
          <ixx>0.000083333</ixx>
          <ixy>0</ixy>
          <ixz>0</ixz>
          <iyy>0.000243333</iyy>
          <iyz>0</iyz>
          <izz>0.000243333</izz>
        </inertia>
      </inertial>
      <collision name='LForeArm_collision'>
        <pose>0 0 0 0 -0 0</pose>
        <geometry>
          <box>
            <size>0.11 0.05 0.05</size>
          </box>
        </geometry>
        <surface>
          <contact>
            <ode/>
          </contact>
          <friction>
            <ode>
              <mu>0.5</mu>
              <mu2>0.5</mu2>
            </ode>
          </friction>
        </surface>
      </collision>
      <visual name='LForeArm_visual'>
        <pose>-0.03 0 0 0 -0 0</pose>
        <geometry>
          <mesh>
            <scale>0.13 0.1 0.1</scale>
            <uri>model://nao_blue/meshes/V40/LWristYaw.dae</uri>
          </mesh>
        </geometry>
      </visual>
      <gravity>1</gravity>
      <velocity_decay/>
      <self_collide>0</self_collide>
    </link>
    <joint name='LElbowRoll' type='revolute'>
      <child>LForeArm</child>
      <pose>-0.05 0 0 0 -0 0</pose>
      <parent>LElbow</parent>
      <axis>
        <xyz>0 0 1</xyz>
        <limit>
          <lower>-1.570796</lower>
          <upper>0.017453</upper>
          <effort>40.25</effort>
          <velocity>6.1395</velocity>
        </limit>
        <dynamics>
          <damping>0.1</damping>
          <friction>0</friction>
          <spring_reference>0</spring_reference>
          <spring_stiffness>0</spring_stiffness>
        </dynamics>
        <use_parent_model_frame>1</use_parent_model_frame>
      </axis>
      <physics>
        <ode>
          <implicit_spring_damper>1</implicit_spring_damper>
          <cfm_damping>1</cfm_damping>
          <limit>
            <cfm>0</cfm>
            <erp>0.2</erp>
          </limit>
        </ode>
      </physics>
    </joint>

    <link name='RHip1'>
      <pose>0 -0.055 -0.115 0 -0 0</pose>
      <inertial>
        <pose>0 0 0 0 -0 0</pose>
        <mass>0.09</mass>
        <inertia>
          <ixx>0.0000036</ixx>
          <iyy>0.0000036</iyy>
          <izz>0.0000036</izz>
          <ixy>0</ixy>
          <ixz>0</ixz>
          <iyz>0</iyz>
        </inertia>
      </inertial>

      <visual name='RHip1_visual'>
        <pose>0 0 0 0 -0 0</pose>
        <geometry>
          <mesh>
            <scale>0.1 0.1 0.1</scale>
            <uri>model://nao_blue/meshes/V40/RHipYawPitch.dae</uri>
          </mesh>
        </geometry>
      </visual>
      <gravity>1</gravity>
      <velocity_decay/>
      <self_collide>0</self_collide>
    </link>
    <joint name='RHipYawPitch' type='revolute'>
      <child>RHip1</child>
      <pose>-0.01 0 0 0 0 0</pose>		
      <parent>base_link</parent>
      <axis>
        <xyz>0 0.7071 0.7071</xyz>
        <limit>
          <lower>-1.57079</lower>
          <upper>0.017453</upper>
          <effort>100</effort>
          <velocity>6.1395</velocity>
        </limit>
        <dynamics>
          <damping>0.1</damping>
          <friction>0</friction>
          <spring_reference>0</spring_reference>
          <spring_stiffness>0</spring_stiffness>
        </dynamics>
        <use_parent_model_frame>1</use_parent_model_frame>
      </axis>
      <physics>
        <ode>
          <implicit_spring_damper>1</implicit_spring_damper>
          <cfm_damping>1</cfm_damping>
          <limit>
            <cfm>0</cfm>
            <erp>0.2</erp>
          </limit>
        </ode>
      </physics>
    </joint>
    <link name='RHip'>
      <pose>0 -0.055 -0.115 0 -0 0</pose>
      <inertial>
        <pose>0 0 0 0 -0 0</pose>
        <mass>0.125</mass>
        <inertia>
          <ixx>0.000005</ixx>
          <iyy>0.000005</iyy>
          <izz>0.000005</izz>
          <ixy>0</ixy>
          <ixz>0</ixz>
          <iyz>0</iyz>
        </inertia>
      </inertial>
      <visual name='RHip_visual'>
        <pose>0 0 0 0 -0 0</pose>
        <geometry>
          <mesh>
            <scale>0.1 0.1 0.1</scale>
            <uri>model://nao_blue/meshes/V40/RHipRoll.dae</uri>
          </mesh>
        </geometry>
      </visual>
      <gravity>1</gravity>
      <velocity_decay/>
      <self_collide>0</self_collide>
    </link>
    <joint name='RHipRoll' type='revolute'>
      <child>RHip</child>
	  <pose>-0.01 0 0 0 0 0</pose>		
      <parent>RHip1</parent>
      <axis>
        <xyz>1 0 0</xyz>
        <limit>
          <lower>-0.785398</lower>
          <upper>0.436332</upper>
          <effort>200</effort>
          <velocity>6.1395</velocity>
        </limit>
        <dynamics>
          <damping>0.1</damping>
          <friction>0</friction>
          <spring_reference>0</spring_reference>
          <spring_stiffness>0</spring_stiffness>
        </dynamics>
        <use_parent_model_frame>1</use_parent_model_frame>
      </axis>
      <physics>
        <ode>
          <implicit_spring_damper>1</implicit_spring_damper>
          <cfm_damping>1</cfm_damping>
          <limit>
            <cfm>0</cfm>
            <erp>0.2</erp>
          </limit>
        </ode>
      </physics>
    </joint>
    <link name='RThigh'>
      <pose>0 -0.055 -0.155 0 -0 0</pose>
      <inertial>
        <pose>0 0 0 0 0 0</pose>
        <mass>0.275</mass>
        <inertia>
          <ixx>0.00056145</ixx>
          <iyy>0.00056145</iyy>
          <izz>0.00022458</izz>
          <ixy>0</ixy>
          <ixz>0</ixz>
          <iyz>0</iyz>
        </inertia>
      </inertial>
      <collision name='RThigh_collision'>
        <pose>0 0 0 0 -0 0</pose>
        <geometry>
          <box>
            <size>0.070 0.070 0.14</size>
          </box>
        </geometry>
        <surface>
          <contact>
            <ode/>
          </contact>
          <friction>
            <ode>
              <mu>0.5</mu>
              <mu2>0.5</mu2>
            </ode>
          </friction>
        </surface>
      </collision>
      <visual name='RThigh_visual'>
        <pose>0.01 0 0.04 0 -0 0</pose>
        <geometry>
          <mesh>
            <scale>0.1 0.1 0.12</scale>
            <uri>model://nao_blue/meshes/V40/RHipPitch.dae</uri>
          </mesh>
        </geometry>
      </visual>
      <gravity>1</gravity>
      <velocity_decay/>
      <self_collide>0</self_collide>
    </link>
    <joint name='RHipPitch' type='revolute'>
      <child>RThigh</child>
      <pose>-0.01 0 0.04 0 -0 0</pose>
      <parent>RHip</parent>
      <axis>
        <xyz>0 -1 0</xyz>
        <limit>
          <lower>-0.436332</lower>
          <upper>1.53589</upper>
          <effort>300</effort>
          <velocity>6.40239</velocity>
        </limit>
        <dynamics>
          <damping>0.1</damping>
          <friction>0</friction>
          <spring_reference>0</spring_reference>
          <spring_stiffness>0</spring_stiffness>
        </dynamics>
        <use_parent_model_frame>1</use_parent_model_frame>
      </axis>
      <physics>
        <ode>
          <implicit_spring_damper>1</implicit_spring_damper>
          <cfm_damping>1</cfm_damping>
          <limit>
            <cfm>0</cfm>
            <erp>0.2</erp>
          </limit>
        </ode>
      </physics>
    </joint>
    <link name='RTibia'>
      <pose>0.005 -0.055 -0.280 0 -0 0</pose>
      <inertial>
        <pose>0 0 0 0 -0 0</pose>
        <mass>0.225 </mass>
        <inertia>
          <ixx>0.0003468</ixx>
          <iyy>0.0003187</iyy>
          <izz>0.0002118</izz>
          <ixy>0</ixy>
          <ixz>0</ixz>
          <iyz>0</iyz>
        </inertia>
      </inertial>
      <collision name='RTibia_collision'>
        <pose>0 0 0 0 -0 0</pose>
        <geometry>
          <box>
            <size>0.070 0.080 0.11</size>
          </box>
        </geometry>
        <surface>
          <contact>
            <ode/>
          </contact>
          <friction>
            <ode>
              <mu>0.5</mu>
              <mu2>0.5</mu2>
            </ode>
          </friction>
        </surface>
      </collision>
      <visual name='RTibia_visual'>
        <pose>0 0 0.05 0 -0 0</pose>
        <geometry>
          <mesh>
            <scale>0.1 0.1 0.11</scale>
            <uri>model://nao_blue/meshes/V40/RKneePitch.dae</uri>
          </mesh>
        </geometry>
      </visual>
      <gravity>1</gravity>
      <velocity_decay/>
      <self_collide>0</self_collide>
    </link>
    <joint name='RKneePitch' type='revolute'>
      <child>RTibia</child>
      <pose>0 0 0.045 0 -0 0</pose>
      <parent>RThigh</parent>
      <axis>
        <xyz>0 -1 0</xyz>
        <limit>
          <lower>-2.268928</lower>
          <upper>0.017453</upper>
          <effort>300</effort>
          <velocity>6.40239</velocity>
        </limit>
        <dynamics>
          <damping>0.1</damping>
          <friction>0</friction>
          <spring_reference>0</spring_reference>
          <spring_stiffness>0</spring_stiffness>
        </dynamics>
        <use_parent_model_frame>1</use_parent_model_frame>
      </axis>
      <physics>
        <ode>
          <implicit_spring_damper>1</implicit_spring_damper>
          <cfm_damping>1</cfm_damping>
          <limit>
            <cfm>0</cfm>
            <erp>0.2</erp>
          </limit>
        </ode>
      </physics>
    </joint>
    <link name='r_ankle'>
      <pose>0 -0.055 -0.335 0 -0 0</pose>
      <inertial>
        <pose>0.00045 -0.00029 0.00685 0 -0 0</pose>
        <mass>0.125</mass>
        <inertia>
          <ixx>0.000005</ixx>
          <iyy>0.000005</iyy>
          <izz>0.000005</izz>
          <ixy>0</ixy>
          <ixz>0</ixz>
          <iyz>0</iyz>
        </inertia>
      </inertial>
      <visual name='r_ankle_visual'>
        <pose>0 0 0.0 0 -0 0</pose>
        <geometry>
          <mesh>
            <scale>0.1 0.1 0.1</scale>
            <uri>model://nao_blue/meshes/V40/RAnklePitch.dae</uri>
          </mesh>
        </geometry>
      </visual>
      <gravity>1</gravity>
      <velocity_decay/>
      <self_collide>0</self_collide>
    </link>
    <joint name='RAnklePitch' type='revolute'>
      <child>r_ankle</child>
	  <pose>-0.005 0 0 0 0 0</pose>	
      <parent>RTibia</parent>
      <axis>
        <xyz>0 -1 0</xyz>
        <limit>
          <lower>-0.785398</lower>
          <upper>1.308996</upper>
          <effort>300</effort>
          <velocity>6.40239</velocity>
        </limit>
        <dynamics>
          <damping>0.1</damping>
          <friction>0</friction>
          <spring_reference>0</spring_reference>
          <spring_stiffness>0</spring_stiffness>
        </dynamics>
        <use_parent_model_frame>1</use_parent_model_frame>
      </axis>
      <physics>
        <ode>
          <implicit_spring_damper>1</implicit_spring_damper>
          <cfm_damping>1</cfm_damping>
          <limit>
            <cfm>0</cfm>
            <erp>0.2</erp>
          </limit>
        </ode>
      </physics>
    </joint>
    <link name='r_sole'>
      <pose>0 -0.055 -0.375 0 -0 0</pose>
      <inertial>
        <pose>0.025 0 0 0 -0 0</pose>
        <mass>0.2</mass>
        <inertia>
          <ixx>0.00011333</ixx>
          <iyy>0.00043333</iyy>
          <izz>0.00053333</izz>
          <ixy>0</ixy>
          <ixz>0</ixz>
          <iyz>0</iyz>
        </inertia>
      </inertial>
      <collision name='r_sole_collision'>
        <pose>0.025 0.0 0.0 0 -0 0</pose>
        <geometry>
          <box>
            <size>0.16 0.08 0.02</size>
          </box>
        </geometry>
        <surface>
          <contact>
            <ode>
              <max_vel>0.1</max_vel>
              <min_depth>0.003</min_depth>
            </ode>
          </contact>
          <friction>
            <ode>
              <mu>0.5</mu>
              <mu2>0.5</mu2>
              <fdir1>1 0 0</fdir1>
            </ode>
          </friction>
        </surface>
      </collision>
      <visual name='r_sole_visual'>
        <pose>0 0 0.03 0 -0 0</pose>
        <geometry>
          <mesh>
            <scale>0.1 0.1 0.1</scale>
            <uri>model://nao_blue/meshes/V40/RAnkleRoll.dae</uri>
          </mesh>
        </geometry>
      </visual>
      <gravity>1</gravity>
      <velocity_decay/>
      <self_collide>0</self_collide>
    </link>
    <joint name='RAnkleRoll' type='revolute'>
      <child>r_sole</child>
      <pose>-0.005 0 0.04 0 0 0</pose>
      <parent>r_ankle</parent>
      <axis>
        <xyz>1 0 0</xyz>
        <limit>
          <lower>-0.436332</lower>
          <upper>0.785398</upper>
          <effort>200</effort>
          <velocity>6.1395</velocity>
        </limit>
        <dynamics>
          <damping>0.1</damping>
          <friction>0</friction>
          <spring_reference>0</spring_reference>
          <spring_stiffness>0</spring_stiffness>
        </dynamics>
        <use_parent_model_frame>1</use_parent_model_frame>
      </axis>
      <physics>
        <ode>
          <implicit_spring_damper>1</implicit_spring_damper>
          <cfm_damping>1</cfm_damping>
          <limit>
            <cfm>0</cfm>
            <erp>0.2</erp>
          </limit>
        </ode>
      </physics>
    </joint>
    <link name='RShoulder'>
      <pose>0 -0.098 0.075 0 -0 0</pose>
      <inertial>
        <pose>0 0 0 0 0 0</pose>
        <mass>0.07</mass>
        <inertia>
          <ixx>0</ixx>
          <ixy>0</ixy>
          <ixz>0</ixz>
          <iyy>0</iyy>
          <iyz>0</iyz>
          <izz>0</izz>
        </inertia>
      </inertial>
      <visual name='RShoulder_visual'>
        <pose>0 0 0 0 -0 0</pose>
        <geometry>
          <mesh>
            <scale>0.1 0.1 0.11</scale>
            <uri>model://nao_blue/meshes/V40/RShoulderPitch.dae</uri>
          </mesh>
        </geometry>
      </visual>
      <gravity>1</gravity>
      <velocity_decay/>
      <self_collide>0</self_collide>
    </link>
    <joint name='RShoulderPitch' type='revolute'>
      <child>RShoulder</child>
      <parent>base_link</parent>
      <axis>
        <xyz>0 -1 0</xyz>
        <limit>
          <lower>-2.094395</lower>
          <upper>2.094395</upper>
          <effort>40.25</effort>
          <velocity>6.1395</velocity>
        </limit>
        <dynamics>
          <damping>0.1</damping>
          <friction>0</friction>
          <spring_reference>0</spring_reference>
          <spring_stiffness>0</spring_stiffness>
        </dynamics>
        <use_parent_model_frame>1</use_parent_model_frame>
      </axis>
      <physics>
        <ode>
          <implicit_spring_damper>1</implicit_spring_damper>
          <cfm_damping>1</cfm_damping>
          <limit>
            <cfm>0</cfm>
            <erp>0.2</erp>
          </limit>
        </ode>
      </physics>
    </joint>
    <link name='RBicep'>
      <pose>0.02 -0.108 0.075 0 -0 0</pose>
      <inertial>
        <pose>0 -0 0 0 -0 0</pose>
        <mass>0.15</mass>
        <inertia>
          <ixx>0.00010625</ixx>
          <ixy>0</ixy>
          <ixz>0</ixz>
          <iyy>0.00014125</iyy>
          <iyz>0</iyz>
          <izz>0.000125</izz>
        </inertia>
      </inertial>
      <collision name='RBicep_collision'>
        <pose>0 0 0 0 0 0</pose>
        <geometry>
          <box>
            <size>0.08 0.07 0.06</size>
          </box>
        </geometry>
        <surface>
          <contact>
            <ode/>
          </contact>
          <friction>
            <ode>
              <mu>0.5</mu>
              <mu2>0.5</mu2>
            </ode>
          </friction>
        </surface>
      </collision>
      <visual name='RBicep_visual'>
        <pose>-0.02 0.015 0 0 -0 0</pose>
        <geometry>
          <mesh>
            <scale>0.1 0.1 0.1</scale>
            <uri>model://nao_blue/meshes/V40/RShoulderRoll.dae</uri>
          </mesh>
        </geometry>
      </visual>
      <gravity>1</gravity>
      <velocity_decay/>
      <self_collide>0</self_collide>
    </link>
    <joint name='RShoulderRoll' type='revolute'>
      <child>RBicep</child>
	  <pose>-0.02 0.01 0 0 0 0</pose>
      <parent>RShoulder</parent>
      <axis>
        <xyz>0 0 1</xyz>
        <limit>
          <lower>-1.658062</lower>
          <upper>0.017453</upper>
          <effort>40.25</effort>
          <velocity>6.1395</velocity>
        </limit>
        <dynamics>
          <damping>0.1</damping>
          <friction>0</friction>
          <spring_reference>0</spring_reference>
          <spring_stiffness>0</spring_stiffness>
        </dynamics>
        <use_parent_model_frame>1</use_parent_model_frame>
      </axis>
      <physics>
        <ode>
          <implicit_spring_damper>1</implicit_spring_damper>
          <cfm_damping>1</cfm_damping>
          <limit>
            <cfm>0</cfm>
            <erp>0.2</erp>
          </limit>
        </ode>
      </physics>
    </joint>
    <link name='RElbow'>
      <pose>0.09 -0.098 0.084 0 -0 0</pose>
      <inertial>
        <pose>0 0 0 0 -0 0</pose>
        <mass>0.035</mass>
        <inertia>
          <ixx>0.0000014</ixx>
          <ixy>0</ixy>
          <ixz>0</ixz>
          <iyy>0.0000014</iyy>
          <iyz>0</iyz>
          <izz>0.0000014</izz>
        </inertia>
      </inertial>
      <gravity>1</gravity>
      <velocity_decay/>
      <self_collide>0</self_collide>
    </link>
    <joint name='RElbowYaw' type='revolute'>
      <child>RElbow</child>
      <parent>RBicep</parent>
      <axis>
        <xyz>1 0 0</xyz>
        <limit>
          <lower>-2.094395</lower>
          <upper>2.094395</upper>
          <effort>40.25</effort>
          <velocity>6.1395</velocity>
        </limit>
        <dynamics>
          <damping>0.1</damping>
          <friction>0</friction>
          <spring_reference>0</spring_reference>
          <spring_stiffness>0</spring_stiffness>
        </dynamics>
        <use_parent_model_frame>1</use_parent_model_frame>
      </axis>
      <physics>
        <ode>
          <implicit_spring_damper>1</implicit_spring_damper>
          <cfm_damping>1</cfm_damping>
          <limit>
            <cfm>0</cfm>
            <erp>0.2</erp>
          </limit>
        </ode>
      </physics>
    </joint>
    <link name='RForeArm'>
      <pose>0.14 -0.098 0.084 0 -0 0</pose>
      <inertial>
        <pose>0 0 0 0 0 0</pose>
        <mass>0.2</mass>
        <inertia>
          <ixx>0.000083333</ixx>
          <ixy>0</ixy>
          <ixz>0</ixz>
          <iyy>0.000243333</iyy>
          <iyz>0</iyz>
          <izz>0.000243333</izz>
        </inertia>
      </inertial>
      <collision name='RForeArm_collision'>
        <pose>0 0 0 0 -0 0</pose>
        <geometry>
          <box>
            <size>0.11 0.05 0.05</size>
          </box>
        </geometry>
        <surface>
          <contact>
            <ode/>
          </contact>
          <friction>
            <ode>
              <mu>0.5</mu>
              <mu2>0.5</mu2>
            </ode>
          </friction>
        </surface>
      </collision>
      <visual name='RForeArm_visual'>
        <pose>-0.03 0 0 0 0 -0</pose>
        <geometry>
          <mesh>
            <scale>0.13 0.1 0.1</scale>
            <uri>model://nao_blue/meshes/V40/RWristYaw.dae</uri>
          </mesh>
        </geometry>
      </visual>
      <gravity>1</gravity>
      <velocity_decay/>
      <self_collide>0</self_collide>
    </link>
    <joint name='RElbowRoll' type='revolute'>
      <child>RForeArm</child>
      <pose>-0.05 0 0 0 -0 0</pose>
      <parent>RElbow</parent>
      <axis>
        <xyz>0 0 1</xyz>
        <limit>
          <lower>-0.017453</lower>
          <upper>1.570796</upper>
          <effort>40.25</effort>
          <velocity>6.1395</velocity>
        </limit>
        <dynamics>
          <damping>0.1</damping>
          <friction>0</friction>
          <spring_reference>0</spring_reference>
          <spring_stiffness>0</spring_stiffness>
        </dynamics>
        <use_parent_model_frame>1</use_parent_model_frame>
      </axis>
      <physics>
        <ode>
          <implicit_spring_damper>1</implicit_spring_damper>
          <cfm_damping>1</cfm_damping>
          <limit>
            <cfm>0</cfm>
            <erp>0.2</erp>
          </limit>
        </ode>
      </physics>
    </joint>
  </model>
</sdf>
