<sdf version='1.5'>
  <model name='naoType0'>
    <link name='base_link'>
      <pose>0 0 0 0 -0 0</pose>
      <inertial>
        <pose>-0.00413 0 0.04342 0 -0 0</pose>
        <mass>1.2171</mass>
        <inertia>
          <ixx>0.00506234</ixx>
          <ixy>1.43116e-05</ixy>
          <ixz>0.000155191</ixz>
          <iyy>0.00488014</iyy>
          <iyz>-2.70793e-05</iyz>
          <izz>0.0016103</izz>
        </inertia>
      </inertial>
      <collision name='base_link_collision'>
        <pose>0 0 0.01 0 -0 0</pose>
        <geometry>
          <box>
            <size>0.1 0.1 0.18</size>
          </box>
        </geometry>
      </collision>
      <visual name='base_link_visual'>
        <pose>0 0 -0.02 0 -0 0</pose>
        <geometry>
          <mesh>
            <scale>0.1 0.11 0.13</scale>
            <uri>model://nao/meshes/meshes/V40/Torso.dae</uri>
          </mesh>
        </geometry>
      </visual>
      <gravity>1</gravity>
      <velocity_decay/>
      <self_collide>0</self_collide>
    </link>
    <link name='Neck'>
      <pose>0 0 0.09 0 -0 0</pose>
      <inertial>
        <pose>-1e-05 0 -0.02742 0 -0 0</pose>
        <mass>0.05</mass>
        <inertia>
          <ixx>7.4993e-05</ixx>
          <ixy>1.57e-09</ixy>
          <ixz>-1.834e-08</ixz>
          <iyy>7.6e-05</iyy>
          <iyz>-5.295e-08</iyz>
          <izz>5.53373e-06</izz>
        </inertia>
      </inertial>
      <visual name='Neck_visual'>
        <pose>0 0 0.02 0 -0 0</pose>
        <geometry>
          <mesh>
            <scale>0.1 0.1 0.2</scale>
            <uri>model://nao/meshes/meshes/V40/HeadYaw.dae</uri>
          </mesh>
        </geometry>
      </visual>
      <gravity>1</gravity>
      <velocity_decay/>
      <self_collide>0</self_collide>
    </link>
    <joint name='HeadYaw' type='revolute'>
      <child>Neck</child>
      <parent>base_link</parent>
      <axis>
        <xyz>0 0 -1</xyz>
        <limit>
          <lower>-2.0943951</lower>
          <upper>2.0943951</upper>
          <effort>40.25</effort>
          <velocity>8.26797</velocity>
        </limit>
        <dynamics>
          <damping>0.1</damping>
          <friction>0</friction>
          <spring_reference>0</spring_reference>
          <spring_stiffness>0</spring_stiffness>
        </dynamics>
        <use_parent_model_frame>1</use_parent_model_frame>
      </axis>
      <physics>
        <ode>
          <implicit_spring_damper>1</implicit_spring_damper>
          <cfm_damping>1</cfm_damping>
          <limit>
            <cfm>0</cfm>
            <erp>0.2</erp>
          </limit>
        </ode>
      </physics>
    </joint>
    <link name='Head'>
      <pose>0 0 0.155 0 -0 0</pose>
      <inertial>
        <pose>-0.00112 0 0.05258 0 -0 0</pose>
        <mass>0.35</mass>
        <inertia>
          <ixx>0.0026313</ixx>
          <ixy>8.78814e-06</ixy>
          <ixz>4.09847e-05</ixz>
          <iyy>0.00249112</iyy>
          <iyz>-2.99579e-05</iyz>
          <izz>0.000985736</izz>
        </inertia>
      </inertial>
      <collision name='Head_collision'>
        <pose>0 0 0.058 1.57 -0 0</pose>
        <geometry>
          <sphere>
            <radius>0.065</radius>
          </sphere>
        </geometry>
        <surface>
          <contact>
            <ode/>
          </contact>
          <friction>
            <ode>
              <mu>0.5</mu>
              <mu2>0.5</mu2>
            </ode>
          </friction>
        </surface>
      </collision>
      <visual name='Head_visual'>
        <pose>0 0 -0.02 0 -0 0</pose>
        <geometry>
          <mesh>
            <scale>0.1 0.1 0.13</scale>
            <uri>model://nao/meshes/meshes/V40/HeadPitch.dae</uri>
          </mesh>
        </geometry>
      </visual>
      <velocity_decay/>
      <gravity>1</gravity>
      <velocity_decay/>
      <self_collide>0</self_collide>
    </link>
    <joint name='HeadPitch' type='revolute'>
      <child>Head</child>
      <parent>Neck</parent>
      <axis>
        <xyz>0 -1 0</xyz>
        <limit>
          <lower>-0.785398</lower>
          <upper>0.785398</upper>
          <effort>40.25</effort>
          <velocity>6.1395</velocity>
        </limit>
        <dynamics>
          <damping>0.1</damping>
          <friction>0</friction>
          <spring_reference>0</spring_reference>
          <spring_stiffness>0</spring_stiffness>
        </dynamics>
        <use_parent_model_frame>1</use_parent_model_frame>
      </axis>
      <physics>
        <ode>
          <implicit_spring_damper>1</implicit_spring_damper>
          <cfm_damping>1</cfm_damping>
          <limit>
            <cfm>0</cfm>
            <erp>0.2</erp>
          </limit>
        </ode>
      </physics>
    </joint>
    <link name='LHip1'>
      <pose>0 0.055 -0.115 0 -0 0</pose>
      <inertial>
        <pose>-0.00781 -0.01114 0.02661 0 -0 0</pose>
        <mass>0.09</mass>
        <inertia>
          <ixx>8.15023e-05</ixx>
          <ixy>-4.99449e-06</ixy>
          <ixz>1.27482e-05</ixz>
          <iyy>0.000101326</iyy>
          <iyz>2.34547e-05</iyz>
          <izz>6.26236e-05</izz>
        </inertia>
      </inertial>
      <visual name='LHip1_visual'>
        <pose>0 0 0 0 -0 0</pose>
        <geometry>
          <mesh>
            <scale>0.1 0.1 0.1</scale>
            <uri>model://nao/meshes/meshes/V40/LHipYawPitch.dae</uri>
          </mesh>
        </geometry>
      </visual>
      <gravity>1</gravity>
      <velocity_decay/>
      <self_collide>0</self_collide>
    </link>
    <joint name='LHipYawPitch' type='revolute'>
      <child>LHip1</child>
      <parent>base_link</parent>
      <axis>
        <xyz>0 0.7071 -0.7071</xyz>
        <limit>
          <lower>-1.57079</lower>
          <upper>0.017453</upper>
          <effort>100</effort>
          <velocity>6.1395</velocity>
        </limit>
        <dynamics>
          <damping>0.1</damping>
          <friction>0</friction>
          <spring_reference>0</spring_reference>
          <spring_stiffness>0</spring_stiffness>
        </dynamics>
        <use_parent_model_frame>1</use_parent_model_frame>
      </axis>
      <physics>
        <ode>
          <implicit_spring_damper>1</implicit_spring_damper>
          <cfm_damping>1</cfm_damping>
          <limit>
            <cfm>0</cfm>
            <erp>0.2</erp>
          </limit>
        </ode>
      </physics>
    </joint>
    <link name='LHip'>
      <pose>0 0.055 -0.115 0 -0 0</pose>
      <inertial>
        <pose>-0.01549 0.00029 -0.00515 0 -0 0</pose>
        <mass>0.125</mass>
        <inertia>
          <ixx>2.75835e-05</ixx>
          <ixy>-2.233e-08</ixy>
          <ixz>-4.08164e-06</ixz>
          <iyy>9.82706e-05</iyy>
          <iyz>-4.19e-09</iyz>
          <izz>8.80997e-05</izz>
        </inertia>
      </inertial>
      <visual name='LHip_visual'>
        <pose>0 0 0 0 -0 0</pose>
        <geometry>
          <mesh>
            <scale>0.1 0.1 0.1</scale>
            <uri>model://nao/meshes/meshes/V40/LHipRoll.dae</uri>
          </mesh>
        </geometry>
      </visual>
      <gravity>1</gravity>
      <velocity_decay/>
      <self_collide>0</self_collide>
    </link>
    <joint name='LHipRoll' type='revolute'>
      <child>LHip</child>
      <parent>LHip1</parent>
      <axis>
        <xyz>1 0 0</xyz>
        <limit>
          <lower>-0.436332</lower>
          <upper>0.785398</upper>
          <effort>200</effort>
          <velocity>6.1395</velocity>
        </limit>
        <dynamics>
          <damping>0.1</damping>
          <friction>0</friction>
          <spring_reference>0</spring_reference>
          <spring_stiffness>0</spring_stiffness>
        </dynamics>
        <use_parent_model_frame>1</use_parent_model_frame>
      </axis>
      <physics>
        <ode>
          <implicit_spring_damper>1</implicit_spring_damper>
          <cfm_damping>1</cfm_damping>
          <limit>
            <cfm>0</cfm>
            <erp>0.2</erp>
          </limit>
        </ode>
      </physics>
    </joint>
    <link name='LThigh'>
      <pose>0 0.055 -0.155 0 -0 0</pose>
      <inertial>
        <pose>0.00138 0.00221 -0.05373 0 -0 0</pose>
        <mass>0.275</mass>
        <inertia>
          <ixx>0.00163672</ixx>
          <ixy>9.2451e-07</ixy>
          <ixz>8.53067e-05</ixz>
          <iyy>0.00159107</iyy>
          <iyz>3.83616e-05</iyz>
          <izz>0.000303743</izz>
        </inertia>
      </inertial>
      <collision name='LThigh_collision'>
        <pose>0 0 -0.05 0 -0 0</pose>
        <geometry>
          <cylinder>
            <length>0.1</length>
            <radius>0.04</radius>
          </cylinder>
        </geometry>
        <surface>
          <contact>
            <ode/>
          </contact>
          <friction>
            <ode>
              <mu>0.5</mu>
              <mu2>0.5</mu2>
            </ode>
          </friction>
        </surface>
      </collision>
      <visual name='LThigh_visual'>
        <pose>0 0 0 0 -0 0</pose>
        <geometry>
          <mesh>
            <scale>0.1 0.1 0.13</scale>
            <uri>model://nao/meshes/meshes/V40/LHipPitch.dae</uri>
          </mesh>
        </geometry>
      </visual>
      <gravity>1</gravity>
      <velocity_decay/>
      <self_collide>0</self_collide>
    </link>
    <joint name='LHipPitch' type='revolute'>
      <child>LThigh</child>
      <parent>LHip</parent>
      <axis>
        <xyz>0 -1 0</xyz>
        <limit>
          <lower>-0.436332</lower>
          <upper>1.53589</upper>
          <effort>300</effort>
          <velocity>6.40239</velocity>
        </limit>
        <dynamics>
          <damping>0.1</damping>
          <friction>0</friction>
          <spring_reference>0</spring_reference>
          <spring_stiffness>0</spring_stiffness>
        </dynamics>
        <use_parent_model_frame>1</use_parent_model_frame>
      </axis>
      <physics>
        <ode>
          <implicit_spring_damper>1</implicit_spring_damper>
          <cfm_damping>1</cfm_damping>
          <limit>
            <cfm>0</cfm>
            <erp>0.2</erp>
          </limit>
        </ode>
      </physics>
    </joint>
    <link name='LTibia'>
      <pose>0 0.055 -0.280 0 -0 0</pose>
      <inertial>
        <pose>0.00453 0.00225 -0.04936 0 -0 0</pose>
        <mass>0.225 </mass>
        <inertia>
          <ixx>0.00118208</ixx>
          <ixy>6.3362e-07</ixy>
          <ixz>3.6497e-05</ixz>
          <iyy>0.00112865</iyy>
          <iyz>3.94952e-05</iyz>
          <izz>0.000193227</izz>
        </inertia>
      </inertial>
      <collision name='LTibia_collision'>
        <pose>0 0 -0.05 0 -0 0</pose>
        <geometry>
          <cylinder>
            <length>0.1</length>
            <radius>0.04</radius>
          </cylinder>
        </geometry>
        <surface>
          <contact>
            <ode/>
          </contact>
          <friction>
            <ode>
              <mu>0.5</mu>
              <mu2>0.5</mu2>
            </ode>
          </friction>
        </surface>
      </collision>
      <visual name='LTibia_visual'>
        <pose>0 0 0 0 -0 0</pose>
        <geometry>
          <mesh>
            <scale>0.1 0.1 0.11</scale>
            <uri>model://nao/meshes/meshes/V40/LKneePitch.dae</uri>
          </mesh>
        </geometry>
      </visual>
      <gravity>1</gravity>
      <velocity_decay/>
      <self_collide>0</self_collide>
    </link>
    <joint name='LKneePitch' type='revolute'>
      <child>LTibia</child>
      <parent>LThigh</parent>
      <axis>
        <xyz>0 -1 0</xyz>
        <limit>
          <lower>-2.268928</lower>
          <upper>0.017453</upper>
          <effort>300</effort>
          <velocity>6.40239</velocity>
        </limit>
        <dynamics>
          <damping>0.1</damping>
          <friction>0</friction>
          <spring_reference>0</spring_reference>
          <spring_stiffness>0</spring_stiffness>
        </dynamics>
        <use_parent_model_frame>1</use_parent_model_frame>
      </axis>
      <physics>
        <ode>
          <implicit_spring_damper>1</implicit_spring_damper>
          <cfm_damping>1</cfm_damping>
          <limit>
            <cfm>0</cfm>
            <erp>0.2</erp>
          </limit>
        </ode>
      </physics>
    </joint>
    <link name='l_ankle'>
      <pose>0 0.055 -0.335 0 -0 0</pose>
      <inertial>
        <pose>0.00045 0.00029 0.00685 0 -0 0</pose>
        <mass>0.125 </mass>
        <inertia>
          <ixx>3.85098e-05</ixx>
          <ixy>-2.634e-08</ixy>
          <ixz>3.86194e-06</ixz>
          <iyy>7.42653e-05</iyy>
          <iyz>1.834e-08</iyz>
          <izz>5.48654e-05</izz>
        </inertia>
      </inertial>
      <visual name='l_ankle_visual'>
        <pose>0 0 0 0 -0 0</pose>
        <geometry>
          <mesh>
            <scale>0.1 0.1 0.1</scale>
            <uri>model://nao/meshes/meshes/V40/LAnklePitch.dae</uri>
          </mesh>
        </geometry>
      </visual>
      <gravity>1</gravity>
      <velocity_decay/>
      <self_collide>0</self_collide>
    </link>
    <joint name='LAnklePitch' type='revolute'>
      <child>l_ankle</child>
      <parent>LTibia</parent>
      <axis>
        <xyz>0 -1 0</xyz>
        <limit>
          <lower>-0.785398</lower>
          <upper>1.308996</upper>
          <effort>300</effort>
          <velocity>6.40239</velocity>
        </limit>
        <dynamics>
          <damping>0.1</damping>
          <friction>0</friction>
          <spring_reference>0</spring_reference>
          <spring_stiffness>0</spring_stiffness>
        </dynamics>
        <use_parent_model_frame>1</use_parent_model_frame>
      </axis>
      <physics>
        <ode>
          <implicit_spring_damper>1</implicit_spring_damper>
          <cfm_damping>1</cfm_damping>
          <limit>
            <cfm>0</cfm>
            <erp>0.2</erp>
          </limit>
        </ode>
      </physics>
    </joint>
    <link name='l_sole'>
      <pose>0 0.055 -0.375 0 -0 0</pose>
      <inertial>
        <pose>0.02542 0.0033 -0.03239 0 -0 0</pose>
        <mass>0.2</mass>
        <inertia>
          <ixx>0.000269442</ixx>
          <ixy>-5.69572e-06</ixy>
          <ixz>0.000139379</ixz>
          <iyy>0.000644343</iyy>
          <iyz>1.87409e-05</iyz>
          <izz>0.000525757</izz>
        </inertia>
      </inertial>
      <collision name='l_sole_collision'>
        <pose>0.02 0.005 -0.037 0 -0 0</pose>
        <geometry>
          <box>
            <size>0.16 0.085 0.02</size>
          </box>
        </geometry>
        <surface>
          <contact>
            <ode>
              <max_vel>0.1</max_vel>
              <min_depth>0.003</min_depth>
            </ode>
          </contact>
          <friction>
            <ode>
              <mu>0.5</mu>
              <mu2>0.5</mu2>
              <fdir1>1 0 0</fdir1>
            </ode>
          </friction>
        </surface>
      </collision>
      <visual name='l_sole_visual'>
        <pose>0 0 0 0 -0 0</pose>
        <geometry>
          <mesh>
            <scale>0.1 0.1 0.1</scale>
            <uri>model://nao/meshes/meshes/V40/LAnkleRoll.dae</uri>
          </mesh>
        </geometry>
      </visual>
      <gravity>1</gravity>
      <velocity_decay/>
      <self_collide>0</self_collide>
    </link>
    <joint name='LAnkleRoll' type='revolute'>
      <child>l_sole</child>
      <parent>l_ankle</parent>
      <axis>
        <xyz>1 0 0</xyz>
        <limit>
          <lower>-0.785398</lower>
          <upper>0.436332</upper>
          <effort>200</effort>
          <velocity>6.1395</velocity>
        </limit>
        <dynamics>
          <damping>0.1</damping>
          <friction>0</friction>
          <spring_reference>0</spring_reference>
          <spring_stiffness>0</spring_stiffness>
        </dynamics>
        <use_parent_model_frame>1</use_parent_model_frame>
      </axis>
      <physics>
        <ode>
          <implicit_spring_damper>1</implicit_spring_damper>
          <cfm_damping>1</cfm_damping>
          <limit>
            <cfm>0</cfm>
            <erp>0.2</erp>
          </limit>
        </ode>
      </physics>
    </joint>
    <link name='LShoulder'>
      <pose>0 0.098 0.075 0 -0 0</pose>
      <inertial>
        <pose>-0.00165 -0.02663 0.00014 0 -0 0</pose>
        <mass>0.07</mass>
        <inertia>
          <ixx>8.42843e-05</ixx>
          <ixy>-2.02802e-06</ixy>
          <ixz>2.338e-08</ixz>
          <iyy>1.41556e-05</iyy>
          <iyz>-1.972e-08</iyz>
          <izz>8.64195e-05</izz>
        </inertia>
      </inertial>
      <visual name='LShoulder_visual'>
        <pose>0 0 0 0 -0 0</pose>
        <geometry>
          <mesh>
            <scale>0.1 0.1 0.11</scale>
            <uri>model://nao/meshes/meshes/V40/LShoulderPitch.dae</uri>
          </mesh>
        </geometry>
      </visual>
      <gravity>1</gravity>
      <velocity_decay/>
      <self_collide>0</self_collide>
    </link>
    <joint name='LShoulderPitch' type='revolute'>
      <child>LShoulder</child>
      <parent>base_link</parent>
      <axis>
        <xyz>0 -1 0</xyz>
        <limit>
          <lower>-2.094395</lower>
          <upper>2.094395</upper>
          <effort>40.25</effort>
          <velocity>6.1395</velocity>
        </limit>
        <dynamics>
          <damping>0.1</damping>
          <friction>0</friction>
          <spring_reference>0</spring_reference>
          <spring_stiffness>0</spring_stiffness>
        </dynamics>
        <use_parent_model_frame>1</use_parent_model_frame>
      </axis>
      <physics>
        <ode>
          <implicit_spring_damper>1</implicit_spring_damper>
          <cfm_damping>1</cfm_damping>
          <limit>
            <cfm>0</cfm>
            <erp>0.2</erp>
          </limit>
        </ode>
      </physics>
    </joint>
    <link name='LBicep'>
      <pose>0 0.098 0.075 0 -0 0</pose>
      <inertial>
        <pose>0.02455 0.00563 0.0033 0 -0 0</pose>
        <mass>0.15</mass>
        <inertia>
          <ixx>9.38999e-05</ixx>
          <ixy>-4.71445e-05</ixy>
          <ixz>-2.69947e-05</ixz>
          <iyy>0.000371519</iyy>
          <iyz>-2.45977e-06</iyz>
          <izz>0.000341901</izz>
        </inertia>
      </inertial>
      <collision name='LBicep_collision'>
        <pose>0.045 0 0 1.57 -0 1.8</pose>
        <geometry>
          <cylinder>
            <length>0.09</length>
            <radius>0.02</radius>
          </cylinder>
        </geometry>
        <surface>
          <contact>
            <ode/>
          </contact>
          <friction>
            <ode>
              <mu>0.5</mu>
              <mu2>0.5</mu2>
            </ode>
          </friction>
        </surface>
      </collision>
      <visual name='LBicep_visual'>
        <pose>0 0 0 0 -0 0</pose>
        <geometry>
          <mesh>
            <scale>0.1 0.1 0.13</scale>
            <uri>model://nao/meshes/meshes/V40/LShoulderRoll.dae</uri>
          </mesh>
        </geometry>
      </visual>
      <gravity>1</gravity>
      <velocity_decay/>
      <self_collide>0</self_collide>
    </link>
    <joint name='LShoulderRoll' type='revolute'>
      <child>LBicep</child>
      <parent>LShoulder</parent>
      <axis>
        <xyz>0 0 1</xyz>
        <limit>
          <lower>-0.017453</lower>
          <upper>1.658062</upper>
          <effort>40.25</effort>
          <velocity>6.1395</velocity>
        </limit>
        <dynamics>
          <damping>0.1</damping>
          <friction>0</friction>
          <spring_reference>0</spring_reference>
          <spring_stiffness>0</spring_stiffness>
        </dynamics>
        <use_parent_model_frame>1</use_parent_model_frame>
      </axis>
      <physics>
        <ode>
          <implicit_spring_damper>1</implicit_spring_damper>
          <cfm_damping>1</cfm_damping>
          <limit>
            <cfm>0</cfm>
            <erp>0.2</erp>
          </limit>
        </ode>
      </physics>
    </joint>
    <link name='LElbow'>
      <pose>0.95 0.098 0.075 0 -0 0</pose>
      <inertial>
        <pose>-0.02744 0 -0.00014 0 -0 0</pose>
        <mass>0.035</mass>
        <inertia>
          <ixx>5.59715e-06</ixx>
          <ixy>4.21e-09</ixy>
          <ixz>4.319e-08</ixz>
          <iyy>7.54331e-05</iyy>
          <iyz>-1.84e-09</iyz>
          <izz>7.64434e-05</izz>
        </inertia>
      </inertial>
      <gravity>1</gravity>
      <velocity_decay/>
      <self_collide>0</self_collide>
    </link>
    <joint name='LElbowYaw' type='revolute'>
      <child>LElbow</child>
      <parent>LBicep</parent>
      <axis>
        <xyz>1 0 0</xyz>
        <limit>
          <lower>-2.094395</lower>
          <upper>2.094395</upper>
          <effort>40.25</effort>
          <velocity>6.1395</velocity>
        </limit>
        <dynamics>
          <damping>0.1</damping>
          <friction>0</friction>
          <spring_reference>0</spring_reference>
          <spring_stiffness>0</spring_stiffness>
        </dynamics>
        <use_parent_model_frame>1</use_parent_model_frame>
      </axis>
      <physics>
        <ode>
          <implicit_spring_damper>1</implicit_spring_damper>
          <cfm_damping>1</cfm_damping>
          <limit>
            <cfm>0</cfm>
            <erp>0.2</erp>
          </limit>
        </ode>
      </physics>
    </joint>
    <link name='LForeArm'>
      <pose>0.14 0.098 0.084 0 -0 0</pose>
      <inertial>
        <pose>0.02556 0.00281 0.00076 0 -0 0</pose>
        <mass>0.2</mass>
        <inertia>
          <ixx>2.53322e-05</ixx>
          <ixy>-2.34271e-06</ixy>
          <ixz>7.459e-08</ixz>
          <iyy>8.91322e-05</iyy>
          <iyz>-2.655e-08</iyz>
          <izz>8.72873e-05</izz>
        </inertia>
      </inertial>
      <collision name='LForeArm_collision'>
        <pose>0.025325 0 0 1.57 -0 1.57</pose>
        <geometry>
          <cylinder>
            <length>0.055</length>
            <radius>0.02</radius>
          </cylinder>
        </geometry>
        <surface>
          <contact>
            <ode/>
          </contact>
          <friction>
            <ode>
              <mu>0.5</mu>
              <mu2>0.5</mu2>
            </ode>
          </friction>
        </surface>
      </collision>
      <visual name='LForeArm_visual'>
        <pose>0 0 0 0 -0 0</pose>
        <geometry>
          <mesh>
            <scale>0.15 0.1 0.1</scale>
            <uri>model://nao/meshes/meshes/V40/LWristYaw.dae</uri>
          </mesh>
        </geometry>
      </visual>
      <gravity>1</gravity>
      <velocity_decay/>
      <self_collide>0</self_collide>
    </link>
    <joint name='LElbowRoll' type='revolute'>
      <child>LForeArm</child>
      <parent>LElbow</parent>
      <axis>
        <xyz>0 0 1</xyz>
        <limit>
          <lower>-1.570796</lower>
          <upper>0.017453</upper>
          <effort>40.25</effort>
          <velocity>6.1395</velocity>
        </limit>
        <dynamics>
          <damping>0.1</damping>
          <friction>0</friction>
          <spring_reference>0</spring_reference>
          <spring_stiffness>0</spring_stiffness>
        </dynamics>
        <use_parent_model_frame>1</use_parent_model_frame>
      </axis>
      <physics>
        <ode>
          <implicit_spring_damper>1</implicit_spring_damper>
          <cfm_damping>1</cfm_damping>
          <limit>
            <cfm>0</cfm>
            <erp>0.2</erp>
          </limit>
        </ode>
      </physics>
    </joint>

    <link name='RHip1'>
      <pose>0 -0.055 -0.115 0 -0 0</pose>
      <inertial>
        <pose>-0.00781 0.01114 0.02661 0 -0 0</pose>
        <mass>0.09</mass>
        <inertia>
          <ixx>8.9972e-05</ixx>
          <ixy>5.00219e-06</ixy>
          <ixz>1.27352e-05</ixz>
          <iyy>0.000105526</iyy>
          <iyz>-2.77008e-05</iyz>
          <izz>6.68872e-05</izz>
        </inertia>
      </inertial>

      <visual name='RHip1_visual'>
        <pose>0 0 0 0 -0 0</pose>
        <geometry>
          <mesh>
            <scale>0.1 0.1 0.1</scale>
            <uri>model://nao/meshes/meshes/V40/RHipYawPitch.dae</uri>
          </mesh>
        </geometry>
      </visual>
      <gravity>1</gravity>
      <velocity_decay/>
      <self_collide>0</self_collide>
    </link>
    <joint name='RHipYawPitch' type='revolute'>
      <child>RHip1</child>
      <parent>base_link</parent>
      <axis>
        <xyz>0 0.7071 0.7071</xyz>
        <limit>
          <lower>-1.57079</lower>
          <upper>0.017453</upper>
          <effort>100</effort>
          <velocity>6.1395</velocity>
        </limit>
        <dynamics>
          <damping>0.1</damping>
          <friction>0</friction>
          <spring_reference>0</spring_reference>
          <spring_stiffness>0</spring_stiffness>
        </dynamics>
        <use_parent_model_frame>1</use_parent_model_frame>
      </axis>
      <physics>
        <ode>
          <implicit_spring_damper>1</implicit_spring_damper>
          <cfm_damping>1</cfm_damping>
          <limit>
            <cfm>0</cfm>
            <erp>0.2</erp>
          </limit>
        </ode>
      </physics>
    </joint>
    <link name='RHip'>
      <pose>0 -0.055 -0.115 0 -0 0</pose>
      <inertial>
        <pose>-0.01549 -0.00029 -0.00515 0 -0 0</pose>
        <mass>0.125</mass>
        <inertia>
          <ixx>2.75865e-05</ixx>
          <ixy>-1.919e-08</ixy>
          <ixz>-4.10822e-06</ixz>
          <iyy>9.827e-05</iyy>
          <iyz>2.51e-09</iyz>
          <izz>8.81033e-05</izz>
        </inertia>
      </inertial>
      <visual name='RHip_visual'>
        <pose>0 0 0 0 -0 0</pose>
        <geometry>
          <mesh>
            <scale>0.1 0.1 0.1</scale>
            <uri>model://nao/meshes/meshes/V40/RHipRoll.dae</uri>
          </mesh>
        </geometry>
      </visual>
      <gravity>1</gravity>
      <velocity_decay/>
      <self_collide>0</self_collide>
    </link>
    <joint name='RHipRoll' type='revolute'>
      <child>RHip</child>
      <parent>RHip1</parent>
      <axis>
        <xyz>1 0 0</xyz>
        <limit>
          <lower>-0.785398</lower>
          <upper>0.436332</upper>
          <effort>200</effort>
          <velocity>6.1395</velocity>
        </limit>
        <dynamics>
          <damping>0.1</damping>
          <friction>0</friction>
          <spring_reference>0</spring_reference>
          <spring_stiffness>0</spring_stiffness>
        </dynamics>
        <use_parent_model_frame>1</use_parent_model_frame>
      </axis>
      <physics>
        <ode>
          <implicit_spring_damper>1</implicit_spring_damper>
          <cfm_damping>1</cfm_damping>
          <limit>
            <cfm>0</cfm>
            <erp>0.2</erp>
          </limit>
        </ode>
      </physics>
    </joint>
    <link name='RThigh'>
      <pose>0 -0.055 -0.155 0 -0 0</pose>
      <inertial>
        <pose>0.00138 -0.00221 -0.05373 0 -0 0</pose>
        <mass>0.275</mass>
        <inertia>
          <ixx>0.00163748</ixx>
          <ixy>-8.3954e-07</ixy>
          <ixz>8.5883e-05</ixz>
          <iyy>0.00159221</iyy>
          <iyz>-3.91763e-05</iyz>
          <izz>0.000303978</izz>
        </inertia>
      </inertial>
      <visual name='RThigh_visual'>
        <pose>0 0 0 0 -0 0</pose>
        <geometry>
          <mesh>
            <scale>0.1 0.1 0.13</scale>
            <uri>model://nao/meshes/meshes/V40/RHipPitch.dae</uri>
          </mesh>
        </geometry>
      </visual>
      <gravity>1</gravity>
      <velocity_decay/>
      <self_collide>0</self_collide>
    </link>
    <joint name='RHipPitch' type='revolute'>
      <child>RThigh</child>
      <parent>RHip</parent>
      <axis>
        <xyz>0 -1 0</xyz>
        <limit>
          <lower>-0.436332</lower>
          <upper>1.53589</upper>
          <effort>300</effort>
          <velocity>6.40239</velocity>
        </limit>
        <dynamics>
          <damping>0.1</damping>
          <friction>0</friction>
          <spring_reference>0</spring_reference>
          <spring_stiffness>0</spring_stiffness>
        </dynamics>
        <use_parent_model_frame>1</use_parent_model_frame>
      </axis>
      <physics>
        <ode>
          <implicit_spring_damper>1</implicit_spring_damper>
          <cfm_damping>1</cfm_damping>
          <limit>
            <cfm>0</cfm>
            <erp>0.2</erp>
          </limit>
        </ode>
      </physics>
    </joint>
    <link name='RTibia'>
      <pose>0 -0.055 -0.280 0 -0 0</pose>
      <inertial>
        <pose>0.00453 -0.00225 -0.04936 0 -0 0</pose>
        <mass>0.225 </mass>
        <inertia>
          <ixx>0.00118283</ixx>
          <ixy>-8.965e-07</ixy>
          <ixz>2.79969e-05</ixz>
          <iyy>0.00112828</iyy>
          <iyz>-3.8476e-05</iyz>
          <izz>0.000191453</izz>
        </inertia>
      </inertial>
      <collision name='RTibia_collision'>
        <pose>0 0 -0.05 0 -0 0</pose>
        <geometry>
          <cylinder>
            <length>0.1</length>
            <radius>0.04</radius>
          </cylinder>
        </geometry>
        <surface>
          <contact>
            <ode/>
          </contact>
          <friction>
            <ode>
              <mu>0.5</mu>
              <mu2>0.5</mu2>
            </ode>
          </friction>
        </surface>
      </collision>
      <visual name='RTibia_visual'>
        <pose>0 0 0 0 -0 0</pose>
        <geometry>
          <mesh>
            <scale>0.1 0.1 0.11</scale>
            <uri>model://nao/meshes/meshes/V40/RKneePitch.dae</uri>
          </mesh>
        </geometry>
      </visual>
      <gravity>1</gravity>
      <velocity_decay/>
      <self_collide>0</self_collide>
    </link>
    <joint name='RKneePitch' type='revolute'>
      <child>RTibia</child>
      <parent>RThigh</parent>
      <axis>
        <xyz>0 -1 0</xyz>
        <limit>
          <lower>-2.268928</lower>
          <upper>0.017453</upper>
          <effort>300</effort>
          <velocity>6.40239</velocity>
        </limit>
        <dynamics>
          <damping>0.1</damping>
          <friction>0</friction>
          <spring_reference>0</spring_reference>
          <spring_stiffness>0</spring_stiffness>
        </dynamics>
        <use_parent_model_frame>1</use_parent_model_frame>
      </axis>
      <physics>
        <ode>
          <implicit_spring_damper>1</implicit_spring_damper>
          <cfm_damping>1</cfm_damping>
          <limit>
            <cfm>0</cfm>
            <erp>0.2</erp>
          </limit>
        </ode>
      </physics>
    </joint>
    <link name='r_ankle'>
      <pose>0 -0.055 -0.335 0 -0 0</pose>
      <inertial>
        <pose>0.00045 -0.00029 0.00685 0 -0 0</pose>
        <mass>0.125</mass>
        <inertia>
          <ixx>3.85081e-05</ixx>
          <ixy>6.434e-08</ixy>
          <ixz>3.87466e-06</ixz>
          <iyy>7.43108e-05</iyy>
          <iyz>-4.58e-09</iyz>
          <izz>5.49131e-05</izz>
        </inertia>
      </inertial>
      <visual name='r_ankle_visual'>
        <pose>0 0 0 0 -0 0</pose>
        <geometry>
          <mesh>
            <scale>0.1 0.1 0.1</scale>
            <uri>model://nao/meshes/meshes/V40/RAnklePitch.dae</uri>
          </mesh>
        </geometry>
      </visual>
      <gravity>1</gravity>
      <velocity_decay/>
      <self_collide>0</self_collide>
    </link>
    <joint name='RAnklePitch' type='revolute'>
      <child>r_ankle</child>
      <parent>RTibia</parent>
      <axis>
        <xyz>0 -1 0</xyz>
        <limit>
          <lower>-0.785398</lower>
          <upper>1.308996</upper>
          <effort>300</effort>
          <velocity>6.40239</velocity>
        </limit>
        <dynamics>
          <damping>0.1</damping>
          <friction>0</friction>
          <spring_reference>0</spring_reference>
          <spring_stiffness>0</spring_stiffness>
        </dynamics>
        <use_parent_model_frame>1</use_parent_model_frame>
      </axis>
      <physics>
        <ode>
          <implicit_spring_damper>1</implicit_spring_damper>
          <cfm_damping>1</cfm_damping>
          <limit>
            <cfm>0</cfm>
            <erp>0.2</erp>
          </limit>
        </ode>
      </physics>
    </joint>
    <link name='r_sole'>
      <pose>0 -0.055 -0.375 0 -0 0</pose>
      <inertial>
        <pose>0.02542 -0.0033 -0.03239 0 -0 0</pose>
        <mass>0.2</mass>
        <inertia>
          <ixx>0.000269302</ixx>
          <ixy>5.87505e-06</ixy>
          <ixz>0.000139133</ixz>
          <iyy>0.000643474</iyy>
          <iyz>-1.88492e-05</iyz>
          <izz>0.000525035</izz>
        </inertia>
      </inertial>
      <collision name='r_sole_collision'>
        <pose>0.02 -0.005 -0.037 0 -0 0</pose>
        <geometry>
          <box>
            <size>0.16 0.085 0.02</size>
          </box>
        </geometry>
        <surface>
          <contact>
            <ode>
              <max_vel>0.1</max_vel>
              <min_depth>0.003</min_depth>
            </ode>
          </contact>
          <friction>
            <ode>
              <mu>0.5</mu>
              <mu2>0.5</mu2>
              <fdir1>1 0 0</fdir1>
            </ode>
          </friction>
        </surface>
      </collision>
      <visual name='r_sole_visual'>
        <pose>0 0 0 0 -0 0</pose>
        <geometry>
          <mesh>
            <scale>0.1 0.1 0.1</scale>
            <uri>model://nao/meshes/meshes/V40/RAnkleRoll.dae</uri>
          </mesh>
        </geometry>
      </visual>
      <gravity>1</gravity>
      <velocity_decay/>
      <self_collide>0</self_collide>
    </link>
    <joint name='RAnkleRoll' type='revolute'>
      <child>r_sole</child>
      <parent>r_ankle</parent>
      <axis>
        <xyz>1 0 0</xyz>
        <limit>
          <lower>-0.436332</lower>
          <upper>0.785398</upper>
          <effort>200</effort>
          <velocity>6.1395</velocity>
        </limit>
        <dynamics>
          <damping>0.1</damping>
          <friction>0</friction>
          <spring_reference>0</spring_reference>
          <spring_stiffness>0</spring_stiffness>
        </dynamics>
        <use_parent_model_frame>1</use_parent_model_frame>
      </axis>
      <physics>
        <ode>
          <implicit_spring_damper>1</implicit_spring_damper>
          <cfm_damping>1</cfm_damping>
          <limit>
            <cfm>0</cfm>
            <erp>0.2</erp>
          </limit>
        </ode>
      </physics>
    </joint>
    <link name='RShoulder'>
      <pose>0 -0.098 0.075 0 -0 0</pose>
      <inertial>
        <pose>-0.00165 0.02663 0.00014 0 -0 0</pose>
        <mass>0.07</mass>
        <inertia>
          <ixx>8.42843e-05</ixx>
          <ixy>2.02802e-06</ixy>
          <ixz>2.338e-08</ixz>
          <iyy>1.41556e-05</iyy>
          <iyz>1.972e-08</iyz>
          <izz>8.64195e-05</izz>
        </inertia>
      </inertial>
      <visual name='RShoulder_visual'>
        <pose>0 0 0 0 -0 0</pose>
        <geometry>
          <mesh>
            <scale>0.1 0.1 0.11</scale>
            <uri>model://nao/meshes/meshes/V40/RShoulderPitch.dae</uri>
          </mesh>
        </geometry>
      </visual>
      <gravity>1</gravity>
      <velocity_decay/>
      <self_collide>0</self_collide>
    </link>
    <joint name='RShoulderPitch' type='revolute'>
      <child>RShoulder</child>
      <parent>base_link</parent>
      <axis>
        <xyz>0 -1 0</xyz>
        <limit>
          <lower>-2.094395</lower>
          <upper>2.094395</upper>
          <effort>40.25</effort>
          <velocity>6.1395</velocity>
        </limit>
        <dynamics>
          <damping>0.1</damping>
          <friction>0</friction>
          <spring_reference>0</spring_reference>
          <spring_stiffness>0</spring_stiffness>
        </dynamics>
        <use_parent_model_frame>1</use_parent_model_frame>
      </axis>
      <physics>
        <ode>
          <implicit_spring_damper>1</implicit_spring_damper>
          <cfm_damping>1</cfm_damping>
          <limit>
            <cfm>0</cfm>
            <erp>0.2</erp>
          </limit>
        </ode>
      </physics>
    </joint>
    <link name='RBicep'>
      <pose>0 -0.098 0.075 0 -0 0</pose>
      <inertial>
        <pose>0.02455 -0.00563 0.0033 0 -0 0</pose>
        <mass>0.15</mass>
        <inertia>
          <ixx>0.00011012</ixx>
          <ixy>7.66913e-05</ixy>
          <ixz>-2.60461e-05</ixz>
          <iyy>0.000367577</iyy>
          <iyz>1.20983e-05</iyz>
          <izz>0.000354618</izz>
        </inertia>
      </inertial>
      <collision name='RBicep_collision'>
        <pose>0.045 0 0 1.57 0 -1.8</pose>
        <geometry>
          <cylinder>
            <length>0.09</length>
            <radius>0.02</radius>
          </cylinder>
        </geometry>
        <surface>
          <contact>
            <ode/>
          </contact>
          <friction>
            <ode>
              <mu>0.5</mu>
              <mu2>0.5</mu2>
            </ode>
          </friction>
        </surface>
      </collision>
      <visual name='RBicep_visual'>
        <pose>0 0 0 0 -0 0</pose>
        <geometry>
          <mesh>
            <scale>0.1 0.1 0.13</scale>
            <uri>model://nao/meshes/meshes/V40/RShoulderRoll.dae</uri>
          </mesh>
        </geometry>
      </visual>
      <gravity>1</gravity>
      <velocity_decay/>
      <self_collide>0</self_collide>
    </link>
    <joint name='RShoulderRoll' type='revolute'>
      <child>RBicep</child>
      <parent>RShoulder</parent>
      <axis>
        <xyz>0 0 1</xyz>
        <limit>
          <lower>-1.658062</lower>
          <upper>0.017453</upper>
          <effort>40.25</effort>
          <velocity>6.1395</velocity>
        </limit>
        <dynamics>
          <damping>0.1</damping>
          <friction>0</friction>
          <spring_reference>0</spring_reference>
          <spring_stiffness>0</spring_stiffness>
        </dynamics>
        <use_parent_model_frame>1</use_parent_model_frame>
      </axis>
      <physics>
        <ode>
          <implicit_spring_damper>1</implicit_spring_damper>
          <cfm_damping>1</cfm_damping>
          <limit>
            <cfm>0</cfm>
            <erp>0.2</erp>
          </limit>
        </ode>
      </physics>
    </joint>
    <link name='RElbow'>
      <pose>0.95 -0.098 0.075 0 -0 0</pose>
      <inertial>
        <pose>-0.02744 0 -0.00014 0 -0 0</pose>
        <mass>0.035</mass>
        <inertia>
          <ixx>5.59715e-06</ixx>
          <ixy>4.21e-09</ixy>
          <ixz>4.319e-08</ixz>
          <iyy>7.54331e-05</iyy>
          <iyz>-1.84e-09</iyz>
          <izz>7.64434e-05</izz>
        </inertia>
      </inertial>
      <gravity>1</gravity>
      <velocity_decay/>
      <self_collide>0</self_collide>
    </link>
    <joint name='RElbowYaw' type='revolute'>
      <child>RElbow</child>
      <parent>RBicep</parent>
      <axis>
        <xyz>1 0 0</xyz>
        <limit>
          <lower>-2.094395</lower>
          <upper>2.094395</upper>
          <effort>40.25</effort>
          <velocity>6.1395</velocity>
        </limit>
        <dynamics>
          <damping>0.1</damping>
          <friction>0</friction>
          <spring_reference>0</spring_reference>
          <spring_stiffness>0</spring_stiffness>
        </dynamics>
        <use_parent_model_frame>1</use_parent_model_frame>
      </axis>
      <physics>
        <ode>
          <implicit_spring_damper>1</implicit_spring_damper>
          <cfm_damping>1</cfm_damping>
          <limit>
            <cfm>0</cfm>
            <erp>0.2</erp>
          </limit>
        </ode>
      </physics>
    </joint>
    <link name='RForeArm'>
      <pose>0.14 -0.098 0.084 0 -0 0</pose>
      <inertial>
        <pose>0.02556 -0.00281 0.00076 0 -0 0</pose>
        <mass>0.2</mass>
        <inertia>
          <ixx>2.53907e-05</ixx>
          <ixy>2.33243e-06</ixy>
          <ixz>-6.0117e-07</ixz>
          <iyy>8.92204e-05</iyy>
          <iyz>2.694e-08</iyz>
          <izz>8.72484e-05</izz>
        </inertia>
      </inertial>
      <collision name='RForeArm_collision'>
        <pose>0.025325 0 0 1.57 -0 1.57</pose>
        <geometry>
          <cylinder>
            <length>0.055</length>
            <radius>0.02</radius>
          </cylinder>
        </geometry>
        <surface>
          <contact>
            <ode/>
          </contact>
          <friction>
            <ode>
              <mu>0.5</mu>
              <mu2>0.5</mu2>
            </ode>
          </friction>
        </surface>
      </collision>
      <visual name='RForeArm_visual'>
        <pose>0 0 0 0 -0 0</pose>
        <geometry>
          <mesh>
            <scale>0.16 0.1 0.1</scale>
            <uri>model://nao/meshes/meshes/V40/RWristYaw.dae</uri>
          </mesh>
        </geometry>
      </visual>
      <gravity>1</gravity>
      <velocity_decay/>
      <self_collide>0</self_collide>
    </link>
    <joint name='RElbowRoll' type='revolute'>
      <child>RForeArm</child>
      <parent>RElbow</parent>
      <axis>
        <xyz>0 0 1</xyz>
        <limit>
          <lower>-0.017453</lower>
          <upper>1.570796</upper>
          <effort>40.25</effort>
          <velocity>6.1395</velocity>
        </limit>
        <dynamics>
          <damping>0.1</damping>
          <friction>0</friction>
          <spring_reference>0</spring_reference>
          <spring_stiffness>0</spring_stiffness>
        </dynamics>
        <use_parent_model_frame>1</use_parent_model_frame>
      </axis>
      <physics>
        <ode>
          <implicit_spring_damper>1</implicit_spring_damper>
          <cfm_damping>1</cfm_damping>
          <limit>
            <cfm>0</cfm>
            <erp>0.2</erp>
          </limit>
        </ode>
      </physics>
    </joint>
  </model>
</sdf>
